<?xml version="1.0" encoding="UTF-8"?>
<testng-results retried="5" ignored="5" total="15" passed="2" failed="3" skipped="0">
  <reporter-output>
  </reporter-output>
  <suite started-at="2023-12-08T17:20:41 IST" name="Suite" finished-at="2023-12-08T17:21:09 IST" duration-ms="28008">
    <groups>
      <group name="regration">
        <method signature="Test1.log(java.util.HashMap)[pri:0, instance:TestCases.Test1@2767e23c]" name="log" class="TestCases.Test1"/>
      </group> <!-- regration -->
    </groups>
    <test started-at="2023-12-08T17:20:41 IST" name="Test" finished-at="2023-12-08T17:21:09 IST" duration-ms="28008">
      <class name="TestCases.Test1">
        <test-method is-config="true" signature="extentRP()[pri:0, instance:TestCases.Test1@2767e23c]" started-at="2023-12-08T17:20:41 IST" name="extentRP" finished-at="2023-12-08T17:20:41 IST" duration-ms="18" status="PASS">
          <reporter-output>
          </reporter-output>
        </test-method> <!-- extentRP -->
        <test-method retried="true" signature="demo()[pri:0, instance:TestCases.Test1@2767e23c]" started-at="2023-12-08T17:20:41 IST" name="demo" finished-at="2023-12-08T17:20:46 IST" duration-ms="5161" status="SKIP">
          <exception class="java.lang.AssertionError">
            <message>
              <![CDATA[expected [true] but found [false]]]>
            </message>
            <full-stacktrace>
              <![CDATA[java.lang.AssertionError: expected [true] but found [false]
at org.testng.Assert.fail(Assert.java:111)
at org.testng.Assert.failNotEquals(Assert.java:1578)
at org.testng.Assert.assertTrue(Assert.java:57)
at org.testng.Assert.assertTrue(Assert.java:67)
at org.testng.asserts.Assertion$2.doAssert(Assertion.java:96)
at org.testng.asserts.Assertion.executeAssert(Assertion.java:25)
at org.testng.asserts.Assertion.doAssert(Assertion.java:12)
at org.testng.asserts.Assertion.assertTrue(Assertion.java:92)
at TestCases.Test1.demo(Test1.java:101)
at java.base/jdk.internal.reflect.NativeMethodAccessorImpl.invoke0(Native Method)
at java.base/jdk.internal.reflect.NativeMethodAccessorImpl.invoke(NativeMethodAccessorImpl.java:77)
at java.base/jdk.internal.reflect.DelegatingMethodAccessorImpl.invoke(DelegatingMethodAccessorImpl.java:43)
at java.base/java.lang.reflect.Method.invoke(Method.java:568)
at org.testng.internal.invokers.MethodInvocationHelper.invokeMethod(MethodInvocationHelper.java:139)
at org.testng.internal.invokers.TestInvoker.invokeMethod(TestInvoker.java:664)
at org.testng.internal.invokers.TestInvoker.invokeTestMethod(TestInvoker.java:227)
at org.testng.internal.invokers.MethodRunner.runInSequence(MethodRunner.java:50)
at org.testng.internal.invokers.TestInvoker$MethodInvocationAgent.invoke(TestInvoker.java:957)
at org.testng.internal.invokers.TestInvoker.invokeTestMethods(TestInvoker.java:200)
at org.testng.internal.invokers.TestMethodWorker.invokeTestMethods(TestMethodWorker.java:148)
at org.testng.internal.invokers.TestMethodWorker.run(TestMethodWorker.java:128)
at java.base/java.util.concurrent.ThreadPoolExecutor.runWorker(ThreadPoolExecutor.java:1136)
at java.base/java.util.concurrent.ThreadPoolExecutor$Worker.run(ThreadPoolExecutor.java:635)
at java.base/java.lang.Thread.run(Thread.java:842)
]]>
            </full-stacktrace>
          </exception> <!-- java.lang.AssertionError -->
          <reporter-output>
          </reporter-output>
        </test-method> <!-- demo -->
        <test-method retried="true" signature="demo()[pri:0, instance:TestCases.Test1@2767e23c]" started-at="2023-12-08T17:20:46 IST" name="demo" finished-at="2023-12-08T17:20:50 IST" duration-ms="3820" status="SKIP">
          <exception class="java.lang.AssertionError">
            <message>
              <![CDATA[expected [true] but found [false]]]>
            </message>
            <full-stacktrace>
              <![CDATA[java.lang.AssertionError: expected [true] but found [false]
at org.testng.Assert.fail(Assert.java:111)
at org.testng.Assert.failNotEquals(Assert.java:1578)
at org.testng.Assert.assertTrue(Assert.java:57)
at org.testng.Assert.assertTrue(Assert.java:67)
at org.testng.asserts.Assertion$2.doAssert(Assertion.java:96)
at org.testng.asserts.Assertion.executeAssert(Assertion.java:25)
at org.testng.asserts.Assertion.doAssert(Assertion.java:12)
at org.testng.asserts.Assertion.assertTrue(Assertion.java:92)
at TestCases.Test1.demo(Test1.java:101)
at java.base/jdk.internal.reflect.NativeMethodAccessorImpl.invoke0(Native Method)
at java.base/jdk.internal.reflect.NativeMethodAccessorImpl.invoke(NativeMethodAccessorImpl.java:77)
at java.base/jdk.internal.reflect.DelegatingMethodAccessorImpl.invoke(DelegatingMethodAccessorImpl.java:43)
at java.base/java.lang.reflect.Method.invoke(Method.java:568)
at org.testng.internal.invokers.MethodInvocationHelper.invokeMethod(MethodInvocationHelper.java:139)
at org.testng.internal.invokers.TestInvoker.invokeMethod(TestInvoker.java:664)
at org.testng.internal.invokers.TestInvoker.retryFailed(TestInvoker.java:248)
at org.testng.internal.invokers.MethodRunner.runInSequence(MethodRunner.java:62)
at org.testng.internal.invokers.TestInvoker$MethodInvocationAgent.invoke(TestInvoker.java:957)
at org.testng.internal.invokers.TestInvoker.invokeTestMethods(TestInvoker.java:200)
at org.testng.internal.invokers.TestMethodWorker.invokeTestMethods(TestMethodWorker.java:148)
at org.testng.internal.invokers.TestMethodWorker.run(TestMethodWorker.java:128)
at java.base/java.util.concurrent.ThreadPoolExecutor.runWorker(ThreadPoolExecutor.java:1136)
at java.base/java.util.concurrent.ThreadPoolExecutor$Worker.run(ThreadPoolExecutor.java:635)
at java.base/java.lang.Thread.run(Thread.java:842)
]]>
            </full-stacktrace>
          </exception> <!-- java.lang.AssertionError -->
          <reporter-output>
          </reporter-output>
        </test-method> <!-- demo -->
        <test-method retried="true" signature="demo()[pri:0, instance:TestCases.Test1@2767e23c]" started-at="2023-12-08T17:20:50 IST" name="demo" finished-at="2023-12-08T17:20:53 IST" duration-ms="3517" status="SKIP">
          <exception class="java.lang.AssertionError">
            <message>
              <![CDATA[expected [true] but found [false]]]>
            </message>
            <full-stacktrace>
              <![CDATA[java.lang.AssertionError: expected [true] but found [false]
at org.testng.Assert.fail(Assert.java:111)
at org.testng.Assert.failNotEquals(Assert.java:1578)
at org.testng.Assert.assertTrue(Assert.java:57)
at org.testng.Assert.assertTrue(Assert.java:67)
at org.testng.asserts.Assertion$2.doAssert(Assertion.java:96)
at org.testng.asserts.Assertion.executeAssert(Assertion.java:25)
at org.testng.asserts.Assertion.doAssert(Assertion.java:12)
at org.testng.asserts.Assertion.assertTrue(Assertion.java:92)
at TestCases.Test1.demo(Test1.java:101)
at java.base/jdk.internal.reflect.NativeMethodAccessorImpl.invoke0(Native Method)
at java.base/jdk.internal.reflect.NativeMethodAccessorImpl.invoke(NativeMethodAccessorImpl.java:77)
at java.base/jdk.internal.reflect.DelegatingMethodAccessorImpl.invoke(DelegatingMethodAccessorImpl.java:43)
at java.base/java.lang.reflect.Method.invoke(Method.java:568)
at org.testng.internal.invokers.MethodInvocationHelper.invokeMethod(MethodInvocationHelper.java:139)
at org.testng.internal.invokers.TestInvoker.invokeMethod(TestInvoker.java:664)
at org.testng.internal.invokers.TestInvoker.retryFailed(TestInvoker.java:248)
at org.testng.internal.invokers.MethodRunner.runInSequence(MethodRunner.java:62)
at org.testng.internal.invokers.TestInvoker$MethodInvocationAgent.invoke(TestInvoker.java:957)
at org.testng.internal.invokers.TestInvoker.invokeTestMethods(TestInvoker.java:200)
at org.testng.internal.invokers.TestMethodWorker.invokeTestMethods(TestMethodWorker.java:148)
at org.testng.internal.invokers.TestMethodWorker.run(TestMethodWorker.java:128)
at java.base/java.util.concurrent.ThreadPoolExecutor.runWorker(ThreadPoolExecutor.java:1136)
at java.base/java.util.concurrent.ThreadPoolExecutor$Worker.run(ThreadPoolExecutor.java:635)
at java.base/java.lang.Thread.run(Thread.java:842)
]]>
            </full-stacktrace>
          </exception> <!-- java.lang.AssertionError -->
          <reporter-output>
          </reporter-output>
        </test-method> <!-- demo -->
        <test-method retried="true" signature="demo()[pri:0, instance:TestCases.Test1@2767e23c]" started-at="2023-12-08T17:20:53 IST" name="demo" finished-at="2023-12-08T17:20:57 IST" duration-ms="3615" status="SKIP">
          <exception class="java.lang.AssertionError">
            <message>
              <![CDATA[expected [true] but found [false]]]>
            </message>
            <full-stacktrace>
              <![CDATA[java.lang.AssertionError: expected [true] but found [false]
at org.testng.Assert.fail(Assert.java:111)
at org.testng.Assert.failNotEquals(Assert.java:1578)
at org.testng.Assert.assertTrue(Assert.java:57)
at org.testng.Assert.assertTrue(Assert.java:67)
at org.testng.asserts.Assertion$2.doAssert(Assertion.java:96)
at org.testng.asserts.Assertion.executeAssert(Assertion.java:25)
at org.testng.asserts.Assertion.doAssert(Assertion.java:12)
at org.testng.asserts.Assertion.assertTrue(Assertion.java:92)
at TestCases.Test1.demo(Test1.java:101)
at java.base/jdk.internal.reflect.NativeMethodAccessorImpl.invoke0(Native Method)
at java.base/jdk.internal.reflect.NativeMethodAccessorImpl.invoke(NativeMethodAccessorImpl.java:77)
at java.base/jdk.internal.reflect.DelegatingMethodAccessorImpl.invoke(DelegatingMethodAccessorImpl.java:43)
at java.base/java.lang.reflect.Method.invoke(Method.java:568)
at org.testng.internal.invokers.MethodInvocationHelper.invokeMethod(MethodInvocationHelper.java:139)
at org.testng.internal.invokers.TestInvoker.invokeMethod(TestInvoker.java:664)
at org.testng.internal.invokers.TestInvoker.retryFailed(TestInvoker.java:248)
at org.testng.internal.invokers.MethodRunner.runInSequence(MethodRunner.java:62)
at org.testng.internal.invokers.TestInvoker$MethodInvocationAgent.invoke(TestInvoker.java:957)
at org.testng.internal.invokers.TestInvoker.invokeTestMethods(TestInvoker.java:200)
at org.testng.internal.invokers.TestMethodWorker.invokeTestMethods(TestMethodWorker.java:148)
at org.testng.internal.invokers.TestMethodWorker.run(TestMethodWorker.java:128)
at java.base/java.util.concurrent.ThreadPoolExecutor.runWorker(ThreadPoolExecutor.java:1136)
at java.base/java.util.concurrent.ThreadPoolExecutor$Worker.run(ThreadPoolExecutor.java:635)
at java.base/java.lang.Thread.run(Thread.java:842)
]]>
            </full-stacktrace>
          </exception> <!-- java.lang.AssertionError -->
          <reporter-output>
          </reporter-output>
        </test-method> <!-- demo -->
        <test-method retried="true" signature="demo()[pri:0, instance:TestCases.Test1@2767e23c]" started-at="2023-12-08T17:20:57 IST" name="demo" finished-at="2023-12-08T17:21:01 IST" duration-ms="4445" status="SKIP">
          <exception class="java.lang.AssertionError">
            <message>
              <![CDATA[expected [true] but found [false]]]>
            </message>
            <full-stacktrace>
              <![CDATA[java.lang.AssertionError: expected [true] but found [false]
at org.testng.Assert.fail(Assert.java:111)
at org.testng.Assert.failNotEquals(Assert.java:1578)
at org.testng.Assert.assertTrue(Assert.java:57)
at org.testng.Assert.assertTrue(Assert.java:67)
at org.testng.asserts.Assertion$2.doAssert(Assertion.java:96)
at org.testng.asserts.Assertion.executeAssert(Assertion.java:25)
at org.testng.asserts.Assertion.doAssert(Assertion.java:12)
at org.testng.asserts.Assertion.assertTrue(Assertion.java:92)
at TestCases.Test1.demo(Test1.java:101)
at java.base/jdk.internal.reflect.NativeMethodAccessorImpl.invoke0(Native Method)
at java.base/jdk.internal.reflect.NativeMethodAccessorImpl.invoke(NativeMethodAccessorImpl.java:77)
at java.base/jdk.internal.reflect.DelegatingMethodAccessorImpl.invoke(DelegatingMethodAccessorImpl.java:43)
at java.base/java.lang.reflect.Method.invoke(Method.java:568)
at org.testng.internal.invokers.MethodInvocationHelper.invokeMethod(MethodInvocationHelper.java:139)
at org.testng.internal.invokers.TestInvoker.invokeMethod(TestInvoker.java:664)
at org.testng.internal.invokers.TestInvoker.retryFailed(TestInvoker.java:248)
at org.testng.internal.invokers.MethodRunner.runInSequence(MethodRunner.java:62)
at org.testng.internal.invokers.TestInvoker$MethodInvocationAgent.invoke(TestInvoker.java:957)
at org.testng.internal.invokers.TestInvoker.invokeTestMethods(TestInvoker.java:200)
at org.testng.internal.invokers.TestMethodWorker.invokeTestMethods(TestMethodWorker.java:148)
at org.testng.internal.invokers.TestMethodWorker.run(TestMethodWorker.java:128)
at java.base/java.util.concurrent.ThreadPoolExecutor.runWorker(ThreadPoolExecutor.java:1136)
at java.base/java.util.concurrent.ThreadPoolExecutor$Worker.run(ThreadPoolExecutor.java:635)
at java.base/java.lang.Thread.run(Thread.java:842)
]]>
            </full-stacktrace>
          </exception> <!-- java.lang.AssertionError -->
          <reporter-output>
          </reporter-output>
        </test-method> <!-- demo -->
        <test-method signature="demo()[pri:0, instance:TestCases.Test1@2767e23c]" started-at="2023-12-08T17:21:01 IST" name="demo" finished-at="2023-12-08T17:21:06 IST" duration-ms="4888" status="FAIL">
          <exception class="java.lang.AssertionError">
            <message>
              <![CDATA[expected [true] but found [false]]]>
            </message>
            <full-stacktrace>
              <![CDATA[java.lang.AssertionError: expected [true] but found [false]
at org.testng.Assert.fail(Assert.java:111)
at org.testng.Assert.failNotEquals(Assert.java:1578)
at org.testng.Assert.assertTrue(Assert.java:57)
at org.testng.Assert.assertTrue(Assert.java:67)
at org.testng.asserts.Assertion$2.doAssert(Assertion.java:96)
at org.testng.asserts.Assertion.executeAssert(Assertion.java:25)
at org.testng.asserts.Assertion.doAssert(Assertion.java:12)
at org.testng.asserts.Assertion.assertTrue(Assertion.java:92)
at TestCases.Test1.demo(Test1.java:101)
at java.base/jdk.internal.reflect.NativeMethodAccessorImpl.invoke0(Native Method)
at java.base/jdk.internal.reflect.NativeMethodAccessorImpl.invoke(NativeMethodAccessorImpl.java:77)
at java.base/jdk.internal.reflect.DelegatingMethodAccessorImpl.invoke(DelegatingMethodAccessorImpl.java:43)
at java.base/java.lang.reflect.Method.invoke(Method.java:568)
at org.testng.internal.invokers.MethodInvocationHelper.invokeMethod(MethodInvocationHelper.java:139)
at org.testng.internal.invokers.TestInvoker.invokeMethod(TestInvoker.java:664)
at org.testng.internal.invokers.TestInvoker.retryFailed(TestInvoker.java:248)
at org.testng.internal.invokers.MethodRunner.runInSequence(MethodRunner.java:62)
at org.testng.internal.invokers.TestInvoker$MethodInvocationAgent.invoke(TestInvoker.java:957)
at org.testng.internal.invokers.TestInvoker.invokeTestMethods(TestInvoker.java:200)
at org.testng.internal.invokers.TestMethodWorker.invokeTestMethods(TestMethodWorker.java:148)
at org.testng.internal.invokers.TestMethodWorker.run(TestMethodWorker.java:128)
at java.base/java.util.concurrent.ThreadPoolExecutor.runWorker(ThreadPoolExecutor.java:1136)
at java.base/java.util.concurrent.ThreadPoolExecutor$Worker.run(ThreadPoolExecutor.java:635)
at java.base/java.lang.Thread.run(Thread.java:842)
]]>
            </full-stacktrace>
          </exception> <!-- java.lang.AssertionError -->
          <reporter-output>
          </reporter-output>
        </test-method> <!-- demo -->
        <test-method signature="log(java.util.HashMap)[pri:0, instance:TestCases.Test1@2767e23c]" started-at="2023-12-08T17:21:06 IST" name="log" finished-at="2023-12-08T17:21:06 IST" duration-ms="0" status="FAIL">
          <exception class="org.testng.TestNGException">
            <message>
              <![CDATA[
Cannot inject @Test annotated Method [log] with [class java.util.HashMap].
For more information on native dependency injection please refer to https://testng.org/doc/documentation-main.html#native-dependency-injection]]>
            </message>
            <full-stacktrace>
              <![CDATA[org.testng.TestNGException: 
Cannot inject @Test annotated Method [log] with [class java.util.HashMap].
For more information on native dependency injection please refer to https://testng.org/doc/documentation-main.html#native-dependency-injection
at org.testng.internal.Parameters.checkParameterTypes(Parameters.java:436)
at org.testng.internal.Parameters.createParametersForMethod(Parameters.java:350)
at org.testng.internal.Parameters.createParameters(Parameters.java:693)
at org.testng.internal.Parameters.handleParameters(Parameters.java:879)
at org.testng.internal.Parameters.handleParameters(Parameters.java:728)
at org.testng.internal.invokers.ParameterHandler.handleParameters(ParameterHandler.java:72)
at org.testng.internal.invokers.ParameterHandler.createParameters(ParameterHandler.java:51)
at org.testng.internal.invokers.TestInvoker$MethodInvocationAgent.invoke(TestInvoker.java:911)
at org.testng.internal.invokers.TestInvoker.invokeTestMethods(TestInvoker.java:200)
at org.testng.internal.invokers.TestMethodWorker.invokeTestMethods(TestMethodWorker.java:148)
at org.testng.internal.invokers.TestMethodWorker.run(TestMethodWorker.java:128)
at java.base/java.util.concurrent.ThreadPoolExecutor.runWorker(ThreadPoolExecutor.java:1136)
at java.base/java.util.concurrent.ThreadPoolExecutor$Worker.run(ThreadPoolExecutor.java:635)
at java.base/java.lang.Thread.run(Thread.java:842)
]]>
            </full-stacktrace>
          </exception> <!-- org.testng.TestNGException -->
          <reporter-output>
          </reporter-output>
        </test-method> <!-- log -->
        <test-method signature="loginPage()[pri:0, instance:TestCases.Test1@2767e23c]" started-at="2023-12-08T17:21:06 IST" name="loginPage" finished-at="2023-12-08T17:21:09 IST" duration-ms="2457" status="PASS">
          <reporter-output>
          </reporter-output>
        </test-method> <!-- loginPage -->
      </class> <!-- TestCases.Test1 -->
      <class name="TestCases.Test2">
        <test-method signature="test1()[pri:0, instance:TestCases.Test2@5b247367]" started-at="2023-12-08T17:20:41 IST" name="test1" finished-at="2023-12-08T17:20:46 IST" duration-ms="5060" status="PASS">
          <reporter-output>
          </reporter-output>
        </test-method> <!-- test1 -->
        <test-method signature="test12()[pri:0, instance:TestCases.Test2@5b247367]" started-at="2023-12-08T17:20:46 IST" name="test12" finished-at="2023-12-08T17:20:50 IST" duration-ms="3857" status="FAIL">
          <exception class="java.lang.AssertionError">
            <message>
              <![CDATA[expected [true] but found [false]]]>
            </message>
            <full-stacktrace>
              <![CDATA[java.lang.AssertionError: expected [true] but found [false]
at org.testng.Assert.fail(Assert.java:111)
at org.testng.Assert.failNotEquals(Assert.java:1578)
at org.testng.Assert.assertTrue(Assert.java:57)
at org.testng.Assert.assertTrue(Assert.java:67)
at org.testng.asserts.Assertion$2.doAssert(Assertion.java:96)
at org.testng.asserts.Assertion.executeAssert(Assertion.java:25)
at org.testng.asserts.Assertion.doAssert(Assertion.java:12)
at org.testng.asserts.Assertion.assertTrue(Assertion.java:92)
at TestCases.Test2.test12(Test2.java:30)
at java.base/jdk.internal.reflect.NativeMethodAccessorImpl.invoke0(Native Method)
at java.base/jdk.internal.reflect.NativeMethodAccessorImpl.invoke(NativeMethodAccessorImpl.java:77)
at java.base/jdk.internal.reflect.DelegatingMethodAccessorImpl.invoke(DelegatingMethodAccessorImpl.java:43)
at java.base/java.lang.reflect.Method.invoke(Method.java:568)
at org.testng.internal.invokers.MethodInvocationHelper.invokeMethod(MethodInvocationHelper.java:139)
at org.testng.internal.invokers.TestInvoker.invokeMethod(TestInvoker.java:664)
at org.testng.internal.invokers.TestInvoker.invokeTestMethod(TestInvoker.java:227)
at org.testng.internal.invokers.MethodRunner.runInSequence(MethodRunner.java:50)
at org.testng.internal.invokers.TestInvoker$MethodInvocationAgent.invoke(TestInvoker.java:957)
at org.testng.internal.invokers.TestInvoker.invokeTestMethods(TestInvoker.java:200)
at org.testng.internal.invokers.TestMethodWorker.invokeTestMethods(TestMethodWorker.java:148)
at org.testng.internal.invokers.TestMethodWorker.run(TestMethodWorker.java:128)
at java.base/java.util.concurrent.ThreadPoolExecutor.runWorker(ThreadPoolExecutor.java:1136)
at java.base/java.util.concurrent.ThreadPoolExecutor$Worker.run(ThreadPoolExecutor.java:635)
at java.base/java.lang.Thread.run(Thread.java:842)
]]>
            </full-stacktrace>
          </exception> <!-- java.lang.AssertionError -->
          <reporter-output>
          </reporter-output>
        </test-method> <!-- test12 -->
      </class> <!-- TestCases.Test2 -->
    </test> <!-- Test -->
  </suite> <!-- Suite -->
</testng-results>
